<?xml version="1.0"?>

<robot name="pi_robot">

	<!-- * * * Link Definitions * * * -->

 	<link name="base_link">
		<visual>
		    <origin xyz="0 0 0" rpy="0 0 0"/>
			<geometry>
				<box size="4 1 0.5"/>
			</geometry>
			<material name="Cyan1">
	       		<color rgba="1 0 0 1.0"/>
	     	</material>
		</visual>	
	</link>
	
 	<link name="ana_govde_link">
		<visual>
		    <origin xyz="0 0 0.75" rpy="0 0 0"/>
			<geometry>
				<box size="0.5 0.5 2.5"/>
			</geometry>
			<material name="Red">
	       		<color rgba="0.6 0.3 0.3 1.0"/>
	     	</material>
		</visual>	
	</link>
	
	 <link name="donme1_link">
		<visual>
		    <origin xyz="-1.25 0.25 0" rpy="0 0 0"/>
			<geometry>
				<cylinder radius="0.1" length="0.1"/>
			</geometry>
			<material name="Red">
	       		<color rgba="0.4 0.3 0 1.0"/>
	     	</material>
		</visual>	
	</link>
	
	
	<link name="alt_kol_link">
		<visual>
		    <origin xyz="0 0.85 0.65" rpy="0 1.57 1.57"/>
			<geometry>
				<box size="0.1 0.1 1"/>
			</geometry>
			<material name="Blue">
	       		<color rgba="0.4 0.2 1 1.0"/>
	     	</material>
		</visual>	
	</link>
	
	<link name="donme2_link">
		<visual>
		    <origin xyz="-0.05 1.4 0" rpy="0 0 0"/>
			<geometry>
				<cylinder radius="0.1" length="0.1"/>
			</geometry>
			<material name="Red">
	       		<color rgba="0.6 0.21 0.8 1.0"/>
	     	</material>
		</visual>	
	</link>
	

  	<link name="ust_kol_link">
		<visual>
			<origin xyz="0 2 -0.55" rpy="1.57 0 0"/>
			<geometry>
				<cylinder radius="0.05" length="1"/>
			</geometry>
	     	<material name="Green">
				<color rgba="0.4 0.6 0 0"/>
			</material>
	   </visual>
	</link>

	
	<!-- * * * Joint Definitions * * * -->
	
	<joint name="ana_govde_joint" type="prismatic">
    	<parent link="base_link"/>
    	<child link="ana_govde_link"/>
    	<origin xyz="0 0 0.5" rpy="0 0 0"/>
		<axis xyz="1 0 0"/>
		<limit lower="-3.1416" upper="3.1416" effort="10" velocity="3"/>
	</joint>
	
	<joint name="donme1_joint" type="revolute">
    	<parent link="ana_govde_link"/>
    	<child link="donme1_link"/>
    	<origin xyz="0 0 0" rpy="1 0 0"/>
		<axis xyz="0 0 0"/>
		<limit lower="-3.1416" upper="3.1416" effort="10" velocity="3"/>
	</joint>

	<joint name="alt_kol_joint" type="fixed">
    	<parent link="donme1_link"/>
    	<child link="alt_kol_link"/>
    	<origin xyz="-0.6 0 0" rpy="0 -1.57 0"/>	
	</joint>
	
	<joint name="donme2_joint" type="revolute">
    	<parent link="alt_kol_link"/>
    	<child link="donme2_link"/>
    	<origin xyz="0 0 0.6" rpy="0 1.57 0"/>
		<axis xyz="0 0 1"/>
		<limit lower="-3.1416" upper="3.1416" effort="10" velocity="3"/>
	</joint>

	<joint name="ust_kol_joint" type="fixed">
    	<parent link="donme2_link"/>
    	<child link="ust_kol_link"/>
    	<origin xyz="-0.6 0 0" rpy="0 -1.57 0"/>
	</joint>
	

	
	<!-- * * * Joint Definitions * * * 
	<joint name="ana_govde_joint" type="revolute">
    	<parent link="base_link"/>
    	<child link="ana_govde_link"/>
    	<origin xyz="0 0 0.5" rpy="0 0 0"/>
		<axis xyz="0 0 1"/>
		<limit lower="-3.1416" upper="3.1416" effort="10" velocity="3"/>
	</joint>
	
	<joint name="alt_kol_joint" type="revolute">
    	<parent link="ana_govde_link"/>
    	<child link="alt_kol_link"/>
    	<origin xyz="0 0 0" rpy="0 0 0"/>	
		<axis xyz="0 0 1"/>
		<limit lower="-3.1416" upper="3.1416" effort="10" velocity="3"/>
	</joint>

	<joint name="ust_kol_joint" type="revolute">
    	<parent link="alt_kol_link"/>
    	<child link="ust_kol_link"/>
    	<origin xyz="0 0 0" rpy="0 0 0"/>
		<axis xyz="0 0 1"/>
		<limit lower="-3.1416" upper="3.1416" effort="10" velocity="3"/>
	</joint>
	
	-->

</robot>